<?xml version="1.0"?>
<robot name="truck">

  <!-- ================================================================ -->
  <!-- TRUCK - Frame at REAR AXLE (matches x0, y0) -->
  <!-- ================================================================ -->
  <link name="base_link">
    <visual>
      <geometry>
        <!-- Total length: 0.555m -->
        <box size="0.55 0.35 0.05"/>
      </geometry>
      <!-- Frame at rear axle -->
      <origin xyz="0.215 0 0.05" rpy="0 0 0"/>
      <material name="dark_blue">
        <color rgba="0.1 0.2 0.6 1.0"/>
      </material>
    </visual>
  </link>

  <link name="truck_cube">
    <visual>
      <geometry>
        <box size="0.2 0.35 0.19"/>
      </geometry>
      <origin xyz="0 0 0.095" rpy="0 0 0"/>
      <material name="dark_blue">
        <color rgba="0.1 0.2 0.6 1.0"/>
      </material>
    </visual>
  </link>

  <joint name="truck_cube_joint" type="fixed">
    <parent link="base_link"/>
    <child link="truck_cube"/>
    <origin xyz="0.39 0 0.025" rpy="0 0 0"/>
  </joint>

  <!-- Front wheel at L0 = 0.42m forward of rear axle -->
  <link name="front_wheel">
    <visual>
      <geometry>
        <cylinder radius="0.04" length="0.03"/>
      </geometry>
      <origin xyz="0 0 0" rpy="1.57 0 0"/>
      <material name="black">
        <color rgba="0.1 0.1 0.1 1.0"/>
      </material>
    </visual>
  </link>

  <joint name="front_wheel_joint" type="continuous">
    <parent link="base_link"/>
    <child link="front_wheel"/>
    <origin xyz="0.42 0 0.04" rpy="0 0 0"/>
    <axis xyz="0 0 1"/>
  </joint>

  <!-- Rear wheels at frame origin (rear axle) -->
  <link name="rear_left_wheel">
    <visual>
      <geometry>
        <cylinder radius="0.04" length="0.03"/>
      </geometry>
      <origin xyz="0 0 0" rpy="1.57 0 0"/>
      <material name="black">
        <color rgba="0.1 0.1 0.1 1.0"/>
      </material>
    </visual>
  </link>

  <joint name="rear_left_wheel_joint" type="fixed">
    <parent link="base_link"/>
    <child link="rear_left_wheel"/>
    <origin xyz="-0.02 0.1275 0.04" rpy="0 0 0"/>
  </joint>

  <link name="rear_right_wheel">
    <visual>
      <geometry>
        <cylinder radius="0.04" length="0.03"/>
      </geometry>
      <origin xyz="0 0 0" rpy="1.57 0 0"/>
      <material name="black">
        <color rgba="0.1 0.1 0.1 1.0"/>
      </material>
    </visual>
  </link>

  <joint name="rear_right_wheel_joint" type="fixed">
    <parent link="base_link"/>
    <child link="rear_right_wheel"/>
    <origin xyz="-0.02 -0.1275 0.04" rpy="0 0 0"/>
  </joint>

</robot>
